Workbook
Name AnonymBolig3: #REF!
Name AnonymBolig4: #REF!
Name Indeks_info: #REF!
Name Indeks_tabel: #REF!
Name IndeksInfoTable: #REF!
Name MCD_FCM: #REF!
Name Projekter_info: #REF!

Sheet Niveau_1
B1: KLASSIFIKATIONSYSTEM: Uniformat Strukturen
B3: Position | C3: Uniformat Kode | D3: Sammen | E3: Beskrivelse | F3: Benchmarking klassifikation
B4: 1 | C4: A | D4: A. Substructure - Bygningsbasis | E4: Substructure - Bygningsbasis | F4: A. Substructure - Bygningsbasis | H4: A. Substructure - Bygningsbasis
B5: =B4+1 -> 2 | C5: A10 | D5: A10. Foundations - Fundamenter | E5: Foundations - Fundamenter | F5: A. Substructure - Bygningsbasis | H5: B. Shell - Råhus
B6: =B5+1 -> 3 | C6: A1010 | D6: A1010. Standard Foundations - Standard Fundamenter | E6: Standard Foundations - Standard Fundamenter | F6: A. Substructure - Bygningsbasis | H6: C. Interiors - Komplettering
B7: =B6+1 -> 4 | C7: A101001 | D7: A101001. Brøndfundamenter | E7: Brøndfundamenter | F7: A. Substructure - Bygningsbasis | H7: D. Services - Installationer
B8: =B7+1 -> 5 | C8: A101002 | D8: A101002. Liniefundamenter | E8: Liniefundamenter | F8: A. Substructure - Bygningsbasis | H8: E. Equipment & Furnishings - Inventar & Møbler
B9: =B8+1 -> 6 | C9: A101003 | D9: A101003. Punktfundamenter | E9: Punktfundamenter | F9: A. Substructure - Bygningsbasis | H9: F. Special Construction & Demolition - Speciel konstruktion & Nedrivning
B10: =B9+1 -> 7 | C10: A101004 | D10: A101004. Fundamentsbjælker | E10: Fundamentsbjælker | F10: A. Substructure - Bygningsbasis | H10: G. Building Sitework - Grund & Terræn arbejder
B11: =B10+1 -> 8 | C11: A101005 | D11: A101005. Fundamenter isolering | E11: Fundamenter isolering | F11: A. Substructure - Bygningsbasis | H11: H. Byggeplads - Building Site
B12: =B11+1 -> 9 | C12: A101006 | D12: A101006. Pælefundamenter | E12: Pælefundamenter | F12: A. Substructure - Bygningsbasis
B13: =B12+1 -> 10 | C13: A1020 | D13: A1020. Special Foundations - Specielle Fundamenter | E13: Special Foundations - Specielle Fundamenter | F13: A. Substructure - Bygningsbasis | R13: 25000 | S13: 7.5 | T13: 15 | U13: 30 | V13: =(S13+T13*3+U13)/5 -> 16.5 | W13: =V13*R13 -> 412500
B14: =B13+1 -> 11 | C14: A1030 | D14: A1030. Slab on grade - Terrændæk | E14: Slab on grade - Terrændæk | F14: A. Substructure - Bygningsbasis
B15: =B14+1 -> 12 | C15: A103001 | D15: A103001. Terrændæk, kældre | E15: Terrændæk, kældre | F15: A. Substructure - Bygningsbasis
B16: =B15+1 -> 13 | C16: A103002 | D16: A103002. Terrændæk, terrænniveau | E16: Terrændæk, terrænniveau | F16: A. Substructure - Bygningsbasis
B17: =B16+1 -> 14 | C17: A103003 | D17: A103003. Læsserampe | E17: Læsserampe | F17: A. Substructure - Bygningsbasis
B18: =B17+1 -> 15 | C18: A103004 | D18: A103004. Øvrige | E18: Øvrige | F18: A. Substructure - Bygningsbasis
B19: =B18+1 -> 16 | C19: A20 | D19: A20. Basement Construction - Kælder konstruktion | E19: Basement Construction - Kælder konstruktion | F19: A. Substructure - Bygningsbasis
B20: =B19+1 -> 17 | C20: A2010 | D20: A2010. Basement Excavation - Jordarbejde | E20: Basement Excavation - Jordarbejde | F20: A. Substructure - Bygningsbasis
B21: =B20+1 -> 18 | C21: A2020 | D21: A2020. Basement Walls - Inder - Yder- vægge kælder | E21: Basement Walls - Inder - Yder- vægge kælder | F21: A. Substructure - Bygningsbasis
B22: =B21+1 -> 19 | C22: A202001 | D22: A202001. Kælderydervægge, insitu | E22: Kælderydervægge, insitu | F22: A. Substructure - Bygningsbasis
B23: =B22+1 -> 20 | C23: A202002 | D23: A202002. Kælderydervægge, element, leverance | E23: Kælderydervægge, element, leverance | F23: A. Substructure - Bygningsbasis
B24: =B23+1 -> 21 | C24: A202003 | D24: A202003. Støttemure, montage | E24: Støttemure, montage | F24: A. Substructure - Bygningsbasis
B25: =B24+1 -> 22 | C25: A202004 | D25: A202004. Kælderydervægge, element, montage | E25: Kælderydervægge, element, montage | F25: A. Substructure - Bygningsbasis
... B54: =B53+1 -> 51 | C54: B2010 | D54: B2010. Exterior Walls - Udvendige Vægge | E54: Exterior Walls - Udvendige Vægge | F54: B. Shell - Lukning
A55: B10 | B55: =B54+1 -> 52 | C55: B201001 | D55: B201001. Søjler, leverance | E55: Søjler, leverance | F55: B. Shell - Råhus
A56: B10 | B56: =B55+1 -> 53 | C56: B201002 | D56: B201002. Søjler, montage | E56: Søjler, montage | F56: B. Shell - Råhus
B57: =B56+1 -> 54 | C57: B201003 | D57: B201003. Facader | E57: Facader | F57: B. Shell - Lukning
B58: =B57+1 -> 55 | C58: B201004 | D58: B201004. Øvrige - Facader | E58: Øvrige - Facader | F58: B. Shell - Råhus
A59: B10 | B59: =B58+1 -> 56 | C59: B201005 | D59: B201005. Beton elementvægge, leverance | E59: Beton elementvægge, leverance | F59: B. Shell - Råhus
A60: B10 | B60: =B59+1 -> 57 | C60: B201006 | D60: B201006. Beton elementvægge, montage | E60: Beton elementvægge, montage | F60: B. Shell - Råhus
A61: B10 | B61: =B60+1 -> 58 | C61: B201007 | D61: B201007. Stålsøjler | E61: Stålsøjler | F61: B. Shell - Råhus
B62: =B61+1 -> 59 | C62: B201008 | D62: B201008. Murværk, Letklinkeblokke, osv | E62: Murværk, Letklinkeblokke, osv | F62: B. Shell - Lukning
B63: =B62+1 -> 60 | C63: B201009 | D63: B201009. Porebetonskillevægge | E63: Porebetonskillevægge | F63: B. Shell - Lukning
B64: =B63+1 -> 61 | C64: B201010 | D64: B201010. Pudsarbejder | E64: Pudsarbejder | F64: B. Shell - Lukning
B65: =B64+1 -> 62 | C65: B201011 | D65: B201011. Solafskærmning | E65: Solafskærmning | F65: B. Shell - Lukning
A66: B10 | B66: =B65+1 -> 63 | C66: B201012 | D66: B201012. Brandisolering af stål | E66: Brandisolering af stål | F66: B. Shell - Råhus
B67: =B66+1 -> 64 | C67: B2020 | D67: B2020. Exterior Windows - Udvendige Vindue | E67: Exterior Windows - Udvendige Vindue | F67: B. Shell - Lukning
B68: =B67+1 -> 65 | C68: B202001 | D68: B202001. Etablering af vindue i fag | E68: Etablering af vindue i fag | F68: B. Shell - Lukning
B69: =B68+1 -> 66 | C69: B202002 | D69: B202002. Vinduesparti | E69: Vinduesparti | F69: B. Shell - Lukning
...

Sheet Niveau_2
B1: KLASSIFIKATIONSYSTEM: Uniformat Strukturen
B3: Position | C3: Uniformat Kode | D3: Sammen | E3: Beskrivelse | F3: Benchmarking klassifikation
B4: 1 | C4: A | D4: A. Substructure - Bygningsbasis | E4: Substructure - Bygningsbasis | F4: A. Substructure - Bygningsbasis | G4: A10. Foundations - Fundamenter | H4: A20. Basement Construction - Kælder konstruktion
B5: =B4+1 -> 2 | C5: A10 | D5: A10. Foundations - Fundamenter | E5: Foundations - Fundamenter | F5: A. Substructure - Bygningsbasis
B6: =B5+1 -> 3
B7: =B6+1 -> 4
B8: =B7+1 -> 5
B9: =B8+1 -> 6
B10: =B9+1 -> 7
B11: =B10+1 -> 8
B12: =B11+1 -> 9
B13: =B12+1 -> 10 | R13: 25000 | S13: 7.5 | T13: 15 | U13: 30 | V13: 16.5 | W13: 412500
B14: =B13+1 -> 11
B15: =B14+1 -> 12
B16: =B15+1 -> 13
B17: =B16+1 -> 14
B18: =B17+1 -> 15
B19: =B18+1 -> 16 | C19: A20 | D19: A20. Basement Construction - Kælder konstruktion | E19: Basement Construction - Kælder konstruktion | F19: A. Substructure - Bygningsbasis
B20: =B19+1 -> 17
B21: =B20+1 -> 18
B22: =B21+1 -> 19
B23: =B22+1 -> 20
B24: =B23+1 -> 21
B25: =B24+1 -> 22
B26: =B25+1 -> 23
B27: =B26+1 -> 24
B28: =B27+1 -> 25
B29: =B28+1 -> 26
B30: =B29+1 -> 27
B31: =B30+1 -> 28
B32: =B31+1 -> 29
B33: =B32+1 -> 30 | C33: B | D33: B. Shell - Råhus | E33: Shell - Råhus | F33: B. Shell - Råhus | G33: B10. Superstructure - Primære bygningsdele | H33: B20. Exterior Closure - Udvendige arbejde | I33: B30. Roofing - Tag | J33: B40. Interior Walls (concrete)- InderVægge (beton)
B34: =B33+1 -> 31 | C34: B10 | D34: B10. Superstructure - Primære bygningsdele | E34: Superstructure - Primære bygningsdele | F34: B. Shell - Råhus
B35: =B34+1 -> 32
B36: =B35+1 -> 33
B37: =B36+1 -> 34
B38: =B37+1 -> 35
B39: =B38+1 -> 36
B40: =B39+1 -> 37
B41: =B40+1 -> 38
...

Sheet Xlookup_back
A1: Xlookuip back
A2: Liste N1 | B2: Liste N2 | D2: Liste N3
A3: A. Substructure - Bygningsbasis | B3: A. Substructure - Bygningsbasis | C3: A10. Foundations - Fundamenter | D3: =_xlfn.XLOOKUP(E3,$C$3:$C$28,$B$3:$B$28) -> A. Substructure - Bygningsbasis | E3: A10. Foundations - Fundamenter | F3: {=_xlfn.UNIQUE(TRANSPOSE(_xlfn.HSTACK(Niveau_3!G5:K5,Niveau_3!G19:L19,Niveau_3!G34:M34,Niveau_3!G53:K53,Niveau_3!G74:I74,Niveau_3!G77:N77,_xlfn.ANCHORARRAY(Niveau_3!G85),_xlfn.ANCHORARRAY(Niveau_3!G105),_xlfn.ANCHORARRAY(Niveau_3!G115),_xlfn.ANCHORARRAY(Niveau_3!G136),_xlfn.ANCHORARRAY(Niveau_3!G144),_xlfn.ANCHORARRAY(Niveau_3!G161),_xlfn.ANCHORARRAY(Niveau_3!G277),_xlfn.ANCHORARRAY(Niveau_3!G288),_xlfn.ANCHORARRAY(Niveau_3!G324),_xlfn.ANCHORARRAY(Niveau_3!G332),_xlfn.ANCHORARRAY(Niveau_3!G336),_xlfn.ANCHORARRAY(Niveau_3!G342),_xlfn.ANCHORARRAY(Niveau_3!G350),_xlfn.ANCHORARRAY(Niveau_3!G363),_xlfn.ANCHORARRAY(Niveau_3!G380),Niveau_3!G393:K393,Niveau_3!G398:J398)),,TRUE)} -> A1010. Standard Foundations - Standard Fundamenter
A4: B. Shell - Råhus | B4: A. Substructure - Bygningsbasis | C4: A20. Basement Construction - Kælder konstruktion | D4: =_xlfn.XLOOKUP(E4,$C$3:$C$28,$B$3:$B$28) -> A. Substructure - Bygningsbasis | E4: A10. Foundations - Fundamenter | F4: A1020. Special Foundations - Specielle Fundamenter
A5: C. Interiors - Komplettering | B5: B. Shell - Råhus | C5: B10. Superstructure - Primære bygningsdele | D5: =_xlfn.XLOOKUP(E5,$C$3:$C$28,$B$3:$B$28) -> A. Substructure - Bygningsbasis | E5: A10. Foundations - Fundamenter | F5: A1030. Slab on grade - Terrændæk
A6: D. Services - Installationer | B6: B. Shell - Råhus | C6: B20. Exterior Closure - Udvendige arbejde | D6: =_xlfn.XLOOKUP(E6,$C$3:$C$28,$B$3:$B$28) -> A. Substructure - Bygningsbasis | E6: A20. Basement Construction - Kælder konstruktion | F6: A2010. Basement Excavation - Jordarbejde
A7: E. Equipment & Furnishings - Inventar & Møbler | B7: B. Shell - Råhus | C7: B30. Roofing - Tag | D7: =_xlfn.XLOOKUP(E7,$C$3:$C$28,$B$3:$B$28) -> A. Substructure - Bygningsbasis | E7: A20. Basement Construction - Kælder konstruktion | F7: A2020. Basement Walls - Inder - Yder- vægge kælder
A8: F. Special Construction & Demolition - Speciel konstruktion & Nedrivning | B8: B. Shell - Råhus | C8: B40. Interior Walls (concrete)- InderVægge (beton) | D8: =_xlfn.XLOOKUP(E8,$C$3:$C$28,$B$3:$B$28) -> B. Shell - Råhus | E8: B10. Superstructure - Primære bygningsdele | F8: B1010. Floor Construction - Etage dæk konstruktion
A9: G. Building Sitework - Grund & Terræn arbejder | B9: C. Interiors - Komplettering | C9: C10. Interior Construction - Inder Konstruktion | D9: =_xlfn.XLOOKUP(E9,$C$3:$C$28,$B$3:$B$28) -> B. Shell - Råhus | E9: B10. Superstructure - Primære bygningsdele | F9: B1020. Roof Construction - Tag konstruktion
A10: H. Byggeplads - Building Site | B10: C. Interiors - Komplettering | C10: C20. Staircases - Trapper | D10: =_xlfn.XLOOKUP(E10,$C$3:$C$28,$B$3:$B$28) -> B. Shell - Råhus | E10: B20. Exterior Closure - Udvendige arbejde | F10: B2010. Exterior Walls - Udvendige Vægge
B11: C. Interiors - Komplettering | C11: C30. Interior Finishes - Indvendige overflader | D11: =_xlfn.XLOOKUP(E11,$C$3:$C$28,$B$3:$B$28) -> B. Shell - Råhus | E11: B20. Exterior Closure - Udvendige arbejde | F11: B2020. Exterior Windows - Udvendige Vindue
B12: D. Services - Installationer | C12: D10. Conveying Systems - Transportanlæg Systemer | D12: =_xlfn.XLOOKUP(E12,$C$3:$C$28,$B$3:$B$28) -> B. Shell - Råhus | E12: B20. Exterior Closure - Udvendige arbejde | F12: B2030. Exterior Doors - Udvendige Døre
B13: D. Services - Installationer | C13: D20. Plumbing - Vandinstallationer | D13: =_xlfn.XLOOKUP(E13,$C$3:$C$28,$B$3:$B$28) -> B. Shell - Råhus | E13: B30. Roofing - Tag | F13: B3010. Roof Coverings - Tag dækning
B14: D. Services - Installationer | C14: D30. HVAC - VVS | D14: =_xlfn.XLOOKUP(E14,$C$3:$C$28,$B$3:$B$28) -> B. Shell - Råhus | E14: B30. Roofing - Tag | F14: B3020. Roof Openings - Tag åbninger
B15: D. Services - Installationer | C15: D40. Fire Protection - Brand | D15: =_xlfn.XLOOKUP(E15,$C$3:$C$28,$B$3:$B$28) -> B. Shell - Råhus | E15: B40. Interior Walls (concrete)- InderVægge (beton) | F15: B4010. Elevatorskakte
B16: D. Services - Installationer | C16: D50. Electrical - EL | D16: =_xlfn.XLOOKUP(E16,$C$3:$C$28,$B$3:$B$28) -> B. Shell - Råhus | E16: B40. Interior Walls (concrete)- InderVægge (beton) | F16: B4020. Indervægge, leverance
B17: E. Equipment & Furnishings - Inventar & Møbler | C17: E10. Equipment - Inventar | D17: =_xlfn.XLOOKUP(E17,$C$3:$C$28,$B$3:$B$28) -> B. Shell - Råhus | E17: B40. Interior Walls (concrete)- InderVægge (beton) | F17: B4030. Indervægge, montage
B18: E. Equipment & Furnishings - Inventar & Møbler | C18: E20. Furnishings - Møbler | D18: =_xlfn.XLOOKUP(E18,$C$3:$C$28,$B$3:$B$28) -> B. Shell - Råhus | E18: B40. Interior Walls (concrete)- InderVægge (beton) | F18: B4040. Indervægge, insitu
B19: F. Special Construction & Demolition - Speciel konstruktion & Nedrivning | C19: F10. Special Construction - Speciel Konstruktion | D19: =_xlfn.XLOOKUP(E19,$C$3:$C$28,$B$3:$B$28) -> B. Shell - Råhus | E19: B40. Interior Walls (concrete)- InderVægge (beton) | F19: B4050. Udstøbningsblokke, udsparinger og tilstøbninger
B20: F. Special Construction & Demolition - Speciel konstruktion & Nedrivning | C20: F20. Selective Building Demolition - Selektiv Bygning Nedrivning | D20: =_xlfn.XLOOKUP(E20,$C$3:$C$28,$B$3:$B$28) -> B. Shell - Råhus | E20: B40. Interior Walls (concrete)- InderVægge (beton) | F20: B4060. Øvrige beton konstruktioner
B21: G. Building Sitework - Grund & Terræn arbejder | C21: G10. Site Preparation – Forberedelse af Grund | D21: =_xlfn.XLOOKUP(E21,$C$3:$C$28,$B$3:$B$28) -> C. Interiors - Komplettering | E21: C10. Interior Construction - Inder Konstruktion | F21: C1010. Partitions - Skillevægge
B22: G. Building Sitework - Grund & Terræn arbejder | C22: G20. Site Improvements – Grund Forbedringer | D22: =_xlfn.XLOOKUP(E22,$C$3:$C$28,$B$3:$B$28) -> C. Interiors - Komplettering | E22: C10. Interior Construction - Inder Konstruktion | F22: C1020. Interior Doors - Indvendige Døre
... B28: H. Byggeplads - Building Site | C28: H30. Afrigning af byggeplads | D28: =_xlfn.XLOOKUP(E28,$C$3:$C$28,$B$3:$B$28) -> C. Interiors - Komplettering | E28: C30. Interior Finishes - Indvendige overflader | F28: C3030. Ceiling Finishes - Lofter overflader
D29: =_xlfn.XLOOKUP(E29,$C$3:$C$28,$B$3:$B$28) -> D. Services - Installationer | E29: D10. Conveying Systems - Transportanlæg Systemer | F29: D1010. Elevators & Lifts - Elevatorer
D30: =_xlfn.XLOOKUP(E30,$C$3:$C$28,$B$3:$B$28) -> D. Services - Installationer | E30: D10. Conveying Systems - Transportanlæg Systemer | F30: D1020. Escalators & Moving Walks - Rulletrappe og rullende fortov
D31: =_xlfn.XLOOKUP(E31,$C$3:$C$28,$B$3:$B$28) -> D. Services - Installationer | E31: D10. Conveying Systems - Transportanlæg Systemer | F31: D1030. Other Conveying Systems - Øvrige Transportanlæg Systemer
D32: =_xlfn.XLOOKUP(E32,$C$3:$C$28,$B$3:$B$28) -> D. Services - Installationer | E32: D20. Plumbing - Vandinstallationer | F32: D2010. Plumbing Fixtures - Vandinstallation armaturer m.m.
D33: =_xlfn.XLOOKUP(E33,$C$3:$C$28,$B$3:$B$28) -> D. Services - Installationer | E33: D20. Plumbing - Vandinstallationer | F33: D2020. Domestic Water Distribution - Brugsvand fordeling
D34: =_xlfn.XLOOKUP(E34,$C$3:$C$28,$B$3:$B$28) -> D. Services - Installationer | E34: D20. Plumbing - Vandinstallationer | F34: D2030. Sanitary Waste - Sanitet afløb spildevand
D35: =_xlfn.XLOOKUP(E35,$C$3:$C$28,$B$3:$B$28) -> D. Services - Installationer | E35: D20. Plumbing - Vandinstallationer | F35: D2040. Rain Water Drainage - Afvanding regn
D36: =_xlfn.XLOOKUP(E36,$C$3:$C$28,$B$3:$B$28) -> D. Services - Installationer | E36: D20. Plumbing - Vandinstallationer | F36: D2050. Special Plumbing Systems - Specielle vandinstallationer
D37: =_xlfn.XLOOKUP(E37,$C$3:$C$28,$B$3:$B$28) -> D. Services - Installationer | E37: D30. HVAC - VVS | F37: D3010. Energy Supply - Energi forsyning
D38: =_xlfn.XLOOKUP(E38,$C$3:$C$28,$B$3:$B$28) -> D. Services - Installationer | E38: D30. HVAC - VVS | F38: D3020. Heat Generating System - Varmeinstallationer
D39: =_xlfn.XLOOKUP(E39,$C$3:$C$28,$B$3:$B$28) -> D. Services - Installationer | E39: D30. HVAC - VVS | F39: D3030. Cooling Generating System - kølesystem
D40: =_xlfn.XLOOKUP(E40,$C$3:$C$28,$B$3:$B$28) -> D. Services - Installationer | E40: D30. HVAC - VVS | F40: D3040. Distribution System - Ventilation
... D87: =_xlfn.XLOOKUP(E87,$C$3:$C$28,$B$3:$B$28) -> G. Building Sitework - Grund & Terræn arbejder | E87: G50. Other Site Construction – Øvrige Terræn Konstruktion | F87: G5020. Other Site Systems & Equipment – Øvrige Terræn Systemer & Inventar
D88: =_xlfn.XLOOKUP(E88,$C$3:$C$28,$B$3:$B$28) -> H. Byggeplads - Building Site | E88: H10. Etablering af byggeplads
D89: =_xlfn.XLOOKUP(E89,$C$3:$C$28,$B$3:$B$28) -> H. Byggeplads - Building Site | E89: H20. Drift af Byggeplads frem til aflevering
D90: =_xlfn.XLOOKUP(E90,$C$3:$C$28,$B$3:$B$28) -> H. Byggeplads - Building Site | E90: H30. Afrigning af byggeplads

Sheet Xlookup_frem
I3: A10
E4: {=_xlfn.XLOOKUP(I3,F9:F15,G9:N15)} -> #N/A
G7: Niveau 3
F9: A10. Foundations - Fundamenter | G9: A1010. Standard Foundations - Standard Fundamenter | H9: A1020. Special Foundations - Specielle Fundamenter | I9: A1030. Slab on grade - Terrændæk | J9: 0 | K9: 0 | L9: #N/A | M9: #N/A | N9: #N/A
F10: A20. Basement Construction - Kælder konstruktion | G10: A2010. Basement Excavation - Jordarbejde | H10: A2020. Basement Walls - Inder - Yder- vægge kælder | I10: 0 | J10: 0 | K10: 0 | L10: 0 | M10: #N/A | N10: #N/A
F11: B10. Superstructure - Primære bygningsdele | G11: B1010. Floor Construction - Etage dæk konstruktion | H11: B1020. Roof Construction - Tag konstruktion | I11: 0 | J11: 0 | K11: 0 | L11: 0 | M11: 0 | N11: #N/A
F12: B20. Exterior Closure - Udvendige arbejde | G12: B2010. Exterior Walls - Udvendige Vægge | H12: B2020. Exterior Windows - Udvendige Vindue | I12: B2030. Exterior Doors - Udvendige Døre | J12: 0 | K12: 0 | L12: #N/A | M12: #N/A | N12: #N/A
F13: B30. Roofing - Tag | G13: B3010. Roof Coverings - Tag dækning | H13: B3020. Roof Openings - Tag åbninger | I13: 0 | J13: #N/A | K13: #N/A | L13: #N/A | M13: #N/A | N13: #N/A
F14: B40. Interior Walls (concrete)- InderVægge (beton) | G14: B4010. Elevatorskakte | H14: B4020. Indervægge, leverance | I14: B4030. Indervægge, montage | J14: B4040. Indervægge, insitu | K14: B4050. Udstøbningsblokke, udsparinger og tilstøbninger | L14: B4060. Øvrige beton konstruktioner | M14: 0 | N14: 0
F15: C10. Interior Construction - Inder Konstruktion | G15: C1010. Partitions - Skillevægge | H15: C1020. Interior Doors - Indvendige Døre | I15: C1030. Specialties / Fittings - Armaturer / Udstyr | J15: #N/A | K15: #N/A | L15: #N/A | M15: #N/A | N15: #N/A
F16: C20. Staircases - Trapper | G16: C2010. Stair Construction - Trappe konstruktion | H16: C2020. Stair Finishes - Trappe overflader | I16: #N/A | J16: #N/A | K16: #N/A | L16: #N/A | M16: #N/A | N16: #N/A
F17: C30. Interior Finishes - Indvendige overflader | G17: C3010. Wall Finishes - Vægge overflader | H17: C3020. Floor Finishes - Gulve overflader | I17: C3030. Ceiling Finishes - Lofter overflader | J17: #N/A | K17: #N/A | L17: #N/A | M17: #N/A | N17: #N/A
F18: D10. Conveying Systems - Transportanlæg Systemer | G18: D1010. Elevators & Lifts - Elevatorer | H18: D1020. Escalators & Moving Walks - Rulletrappe og rullende fortov | I18: D1030. Other Conveying Systems - Øvrige Transportanlæg Systemer | J18: #N/A | K18: #N/A | L18: #N/A | M18: #N/A | N18: #N/A
F19: D20. Plumbing - Vandinstallationer | G19: D2010. Plumbing Fixtures - Vandinstallation armaturer m.m. | H19: D2020. Domestic Water Distribution - Brugsvand fordeling | I19: D2030. Sanitary Waste - Sanitet afløb spildevand | J19: D2040. Rain Water Drainage - Afvanding regn | K19: D2050. Special Plumbing Systems - Specielle vandinstallationer | L19: #N/A | M19: #N/A | N19: #N/A
F20: D30. HVAC - VVS | G20: D3010. Energy Supply - Energi forsyning | H20: D3020. Heat Generating System - Varmeinstallationer | I20: D3030. Cooling Generating System - kølesystem | J20: D3040. Distribution System - Ventilation | K20: D3050. Terminal & Package Units | L20: D3060. Controls & Instrumentation - Kontrol & Instrumentation | M20: D3070. Special HVAC Systems & Equipment - Speciel VVS Systemer & Inventar | N20: D3080. Systems Testing & Balancing - Systemer test & Afbalancering
F21: D40. Fire Protection - Brand | G21: D4010. Fire Protection Sprinkler Systems - Brand Sprinkling | H21: D4020. Stand-Pipe & Hose Systems - Vandtårn & Slange systemer | I21: D4030. Fire Protection Specialties - Brand Specialiteter | J21: D4040. Other Fire Protection Systems - Øvrige Brand Systemer | K21: #N/A | L21: #N/A | M21: #N/A | N21: #N/A
F22: D50. Electrical - EL | G22: D5010. Electrical Service & Distribution - Elinstallation & Fordeling | H22: D5020. Lighting & Branch Wiring - Belysning & Ledningsføring | I22: D5030. Communication & Security Systems - Kommunikations- & Sikringsanlæg | J22: D5040. Special Electrical Systems - Specielle El Systemer | K22: #N/A | L22: #N/A | M22: #N/A | N22: #N/A
F23: E10. Equipment - Inventar | G23: E1010. Commercial Equipment - Forretnings inventar | H23: E1020. Institutional Equipment - Institutions inventar | I23: E1030. Vehicular Equipment - Mobilt inventar | J23: E1040. Other Equipment - Andet inventar | K23: #N/A | L23: #N/A | M23: #N/A | N23: #N/A
F24: E20. Furnishings - Møbler | G24: E2010. Fixed Furnishings - Fast Møbler | H24: E2020. Movable Furnishings - Løst inventar | I24: #N/A | J24: #N/A | K24: #N/A | L24: #N/A | M24: #N/A | N24: #N/A
F25: F10. Special Construction - Speciel Konstruktion | G25: F1010. Special Structures - Specielle Konstruktioner | H25: F1020. Integrated Construction - Indbygget konstruktioner | I25: F1030. Special Construction Systems - Specielle Konstruktion Systemer | J25: F1040. Special Facilities - Specielle Faciliteter | K25: F1050. Special Controls & Instrumentation - Specielle Kontrol & Instrumentation | L25: #N/A | M25: #N/A | N25: #N/A
F26: F20. Selective Building Demolition - Selektiv Bygning Nedrivning | G26: F2010. Building Elements Demolition - Bygningselementer nedrivning | H26: F2020. Hazardous Components Abatement - Fjernelse af farligt materiale | I26: #N/A | J26: #N/A | K26: #N/A | L26: #N/A | M26: #N/A | N26: #N/A
F27: G10. Site Preparation – Forberedelse af Grund | G27: G1010. Site Clearing – Rydning af Grund | H27: G1020. Site Demolition & Relocation – Grund nedrivning og flytning | I27: G1030. Site Earthwork – Grund jordarbejder | J27: G1040. Hazardous Waste Remediation - Farligt Oprydning affald | K27: #N/A | L27: #N/A | M27: #N/A | N27: #N/A
F28: G20. Site Improvements – Grund Forbedringer | G28: G2010. Roadways – Kørebaner / Vejbaner | H28: G2020. Parking Lots - Parkeringspladser | I28: G2030. Pedestrian Paving - Gågade Brolægning | J28: G2040. Site Development – Udvikling af Grund / Modning | K28: G2050. Landscaping - Landskab | L28: #N/A | M28: #N/A | N28: #N/A
F29: G30. Site Civil / Mechanical Utilities - Grund Bygge / VVS installationer | G29: G3010. Water Supply & Distribution Systems – Vand forsyning & fordeling Systemer | H29: G3020. Sanitary Sewer Systems - Sanitet Kloak Systemer | I29: G3030. Storm Sewer Systems – Storm Kloak Systemer | J29: G3040. Heating Distribution – Varmeinstallationer | K29: G3050. Cooling Distribution - Kølesystem | L29: G3060. Fuel Distribution - Brændstofinstallationer | M29: G3070. Other Civil / Mechanical Utilities – Øvrige Bygge / VVS installationer | N29: #N/A
F30: G40. Site Electrical Utilities – Terræn El installationer | G30: G4010. Electrical Distribution - Elinstallation & Fordeling | H30: G4020. Exterior Lighting – Udvendige Belysning | I30: G4030. Exterior Communications & Security – Udvendige Kommunikation & Sikringsanlæg | J30: G4040. Other Electrical Utilities – Øvrige El installationer | K30: 0 | L30: #N/A | M30: #N/A | N30: #N/A
F31: G50. Other Site Construction – Øvrige Terræn Konstruktion | G31: G5010. Service Tunnels – Service Tunneler | H31: G5020. Other Site Systems & Equipment – Øvrige Terræn Systemer & Inventar | I31: 0 | J31: 0 | K31: #N/A | L31: #N/A | M31: #N/A | N31: #N/A
F32: H10. Etablering af byggeplads
F33: H20. Drift af Byggeplads frem til aflevering
F34: H30. Afrigning af byggeplads
F36: A. Substructure - Bygningsbasis | G36: A10. Foundations - Fundamenter | H36: A20. Basement Construction - Kælder konstruktion
F37: B. Shell - Råhus | G37: B10. Superstructure - Primære bygningsdele | H37: B20. Exterior Closure - Udvendige arbejde | I37: B30. Roofing - Tag | J37: B40. Interior Walls (concrete)- InderVægge (beton)
F38: C. Interiors - Komplettering | G38: C10. Interior Construction - Inder Konstruktion | H38: C20. Staircases - Trapper | I38: C30. Interior Finishes - Indvendige overflader
F39: D. Services - Installationer | G39: D10. Conveying Systems - Transportanlæg Systemer | H39: D20. Plumbing - Vandinstallationer | I39: D30. HVAC - VVS | J39: D40. Fire Protection - Brand | K39: D50. Electrical - EL
F40: E. Equipment & Furnishings - Inventar & Møbler | G40: E10. Equipment - Inventar | H40: E20. Furnishings - Møbler
F41: F. Special Construction & Demolition - Speciel konstruktion & Nedrivning | G41: F10. Special Construction - Speciel Konstruktion | H41: F20. Selective Building Demolition - Selektiv Bygning Nedrivning
F42: G. Building Sitework - Grund & Terræn arbejder | G42: G10. Site Preparation – Forberedelse af Grund | H42: G20. Site Improvements – Grund Forbedringer | I42: G30. Site Civil / Mechanical Utilities - Grund Bygge / VVS installationer | J42: G40. Site Electrical Utilities – Terræn El installationer | K42: G50. Other Site Construction – Øvrige Terræn Konstruktion
F43: H. Byggeplads - Building Site | G43: H10. Etablering af byggeplads | H43: H20. Drift af Byggeplads frem til aflevering | I43: H30. Afrigning af byggeplads
F46: {=_xlfn.UNIQUE(COUNTA(OFFSET($F$36,MATCH(Template!AF3,Xlookup_frem!F36:F43,0)-1,1,,5),),,TRUE)} -> 6
F47: {=_xlfn.UNIQUE(OFFSET($F$36,MATCH(Template!AF3,Xlookup_frem!$F$36:$F$43)-1,1,1,F46),TRUE,TRUE)} -> D10. Conveying Systems - Transportanlæg Systemer | G47: D20. Plumbing - Vandinstallationer | H47: D30. HVAC - VVS | I47: D40. Fire Protection - Brand | J47: D50. Electrical - EL | K47: 0

Sheet Niveau_3
B1: KLASSIFIKATIONSYSTEM: Uniformat Strukturen
B3: Position | C3: Uniformat Kode | D3: Sammen | E3: Beskrivelse | F3: Benchmarking klassifikation
B4: 1 | C4: A | D4: A. Substructure - Bygningsbasis | E4: Substructure - Bygningsbasis | F4: A. Substructure - Bygningsbasis
B5: =B4+1 -> 2 | C5: A10 | D5: A10. Foundations - Fundamenter | E5: Foundations - Fundamenter | F5: A. Substructure - Bygningsbasis | G5: {=TRANSPOSE(_xlfn._xlws.FILTER(D6:D14,D6:D14 <> ""))} -> A1010. Standard Foundations - Standard Fundamenter | H5: A1020. Special Foundations - Specielle Fundamenter | I5: A1030. Slab on grade - Terrændæk
B6: =B5+1 -> 3 | C6: A1010 | D6: A1010. Standard Foundations - Standard Fundamenter | E6: Standard Foundations - Standard Fundamenter | F6: A. Substructure - Bygningsbasis
B7: =B6+1 -> 4
B8: =B7+1 -> 5
B9: =B8+1 -> 6
B10: =B9+1 -> 7
B11: =B10+1 -> 8
B12: =B11+1 -> 9
B13: =B12+1 -> 10 | C13: A1020 | D13: A1020. Special Foundations - Specielle Fundamenter | E13: Special Foundations - Specielle Fundamenter | F13: A. Substructure - Bygningsbasis
B14: =B13+1 -> 11 | C14: A1030 | D14: A1030. Slab on grade - Terrændæk | E14: Slab on grade - Terrændæk | F14: A. Substructure - Bygningsbasis
B15: =B14+1 -> 12
B16: =B15+1 -> 13
B17: =B16+1 -> 14
B18: =B17+1 -> 15
B19: =B18+1 -> 16 | C19: A20 | D19: A20. Basement Construction - Kælder konstruktion | E19: Basement Construction - Kælder konstruktion | F19: A. Substructure - Bygningsbasis | G19: {=TRANSPOSE(_xlfn._xlws.FILTER(D20:D28,D20:D28 <> ""))} -> A2010. Basement Excavation - Jordarbejde | H19: A2020. Basement Walls - Inder - Yder- vægge kælder
B20: =B19+1 -> 17 | C20: A2010 | D20: A2010. Basement Excavation - Jordarbejde | E20: Basement Excavation - Jordarbejde | F20: A. Substructure - Bygningsbasis
B21: =B20+1 -> 18 | C21: A2020 | D21: A2020. Basement Walls - Inder - Yder- vægge kælder | E21: Basement Walls - Inder - Yder- vægge kælder | F21: A. Substructure - Bygningsbasis
B22: =B21+1 -> 19
B23: =B22+1 -> 20
B24: =B23+1 -> 21
B25: =B24+1 -> 22
B26: =B25+1 -> 23
B27: =B26+1 -> 24
B28: =B27+1 -> 25
B29: =B28+1 -> 26
B30: =B29+1 -> 27
B31: =B30+1 -> 28
B32: =B31+1 -> 29
B33: =B32+1 -> 30 | C33: B | D33: B. Shell - Råhus | E33: Shell - Råhus | F33: B. Shell - Råhus
B34: =B33+1 -> 31 | C34: B10 | D34: B10. Superstructure - Primære bygningsdele | E34: Superstructure - Primære bygningsdele | F34: B. Shell - Råhus | G34: {=TRANSPOSE(_xlfn._xlws.FILTER(D35:D52,D35:D52 <> ""))} -> B1010. Floor Construction - Etage dæk konstruktion | H34: B1020. Roof Construction - Tag konstruktion
B35: =B34+1 -> 32 | C35: B1010 | D35: B1010. Floor Construction - Etage dæk konstruktion | E35: Floor Construction - Etage dæk konstruktion | F35: B. Shell - Råhus
B36: =B35+1 -> 33
B37: =B36+1 -> 34
B38: =B37+1 -> 35
B39: =B38+1 -> 36
B40: =B39+1 -> 37
B41: =B40+1 -> 38
...

Sheet Central_classifikation
B1: KLASSIFIKATIONSYSTEM: Uniformat Strukturen
B3: Position | C3: Uniformat Kode | D3: Sammen | E3: Beskrivelse | F3: Benchmarking klassifikation
B4: 1 | C4: A | D4: A. Substructure - Bygningsbasis | E4: Substructure - Bygningsbasis | F4: A. Substructure - Bygningsbasis
B5: =B4+1 -> 2 | C5: A10 | D5: A10. Foundations - Fundamenter | E5: Foundations - Fundamenter | F5: A. Substructure - Bygningsbasis
B6: =B5+1 -> 3 | C6: A1010 | D6: A1010. Standard Foundations - Standard Fundamenter | E6: Standard Foundations - Standard Fundamenter | F6: A. Substructure - Bygningsbasis
B7: =B6+1 -> 4 | C7: A101001 | D7: A101001. Brøndfundamenter | E7: Brøndfundamenter | F7: A. Substructure - Bygningsbasis
B8: =B7+1 -> 5 | C8: A101002 | D8: A101002. Liniefundamenter | E8: Liniefundamenter | F8: A. Substructure - Bygningsbasis
B9: =B8+1 -> 6 | C9: A101003 | D9: A101003. Punktfundamenter | E9: Punktfundamenter | F9: A. Substructure - Bygningsbasis
B10: =B9+1 -> 7 | C10: A101004 | D10: A101004. Fundamentsbjælker | E10: Fundamentsbjælker | F10: A. Substructure - Bygningsbasis
B11: =B10+1 -> 8 | C11: A101005 | D11: A101005. Fundamenter isolering | E11: Fundamenter isolering | F11: A. Substructure - Bygningsbasis
B12: =B11+1 -> 9 | C12: A101006 | D12: A101006. Pælefundamenter | E12: Pælefundamenter | F12: A. Substructure - Bygningsbasis
B13: =B12+1 -> 10 | C13: A1020 | D13: A1020. Special Foundations - Specielle Fundamenter | E13: Special Foundations - Specielle Fundamenter | F13: A. Substructure - Bygningsbasis | R13: 25000 | S13: 7.5 | T13: 15 | U13: 30 | V13: =(S13+T13*3+U13)/5 -> 16.5 | W13: =V13*R13 -> 412500
B14: =B13+1 -> 11 | C14: A1030 | D14: A1030. Slab on grade - Terrændæk | E14: Slab on grade - Terrændæk | F14: A. Substructure - Bygningsbasis
B15: =B14+1 -> 12 | C15: A103001 | D15: A103001. Terrændæk, kældre | E15: Terrændæk, kældre | F15: A. Substructure - Bygningsbasis
B16: =B15+1 -> 13 | C16: A103002 | D16: A103002. Terrændæk, terrænniveau | E16: Terrændæk, terrænniveau | F16: A. Substructure - Bygningsbasis
B17: =B16+1 -> 14 | C17: A103003 | D17: A103003. Læsserampe | E17: Læsserampe | F17: A. Substructure - Bygningsbasis
B18: =B17+1 -> 15 | C18: A103004 | D18: A103004. Øvrige | E18: Øvrige | F18: A. Substructure - Bygningsbasis
B19: =B18+1 -> 16 | C19: A20 | D19: A20. Basement Construction - Kælder konstruktion | E19: Basement Construction - Kælder konstruktion | F19: A. Substructure - Bygningsbasis
B20: =B19+1 -> 17 | C20: A2010 | D20: A2010. Basement Excavation - Jordarbejde | E20: Basement Excavation - Jordarbejde | F20: A. Substructure - Bygningsbasis
B21: =B20+1 -> 18 | C21: A2020 | D21: A2020. Basement Walls - Inder - Yder- vægge kælder | E21: Basement Walls - Inder - Yder- vægge kælder | F21: A. Substructure - Bygningsbasis
B22: =B21+1 -> 19 | C22: A202001 | D22: A202001. Kælderydervægge, insitu | E22: Kælderydervægge, insitu | F22: A. Substructure - Bygningsbasis
B23: =B22+1 -> 20 | C23: A202002 | D23: A202002. Kælderydervægge, element, leverance | E23: Kælderydervægge, element, leverance | F23: A. Substructure - Bygningsbasis
B24: =B23+1 -> 21 | C24: A202003 | D24: A202003. Støttemure, montage | E24: Støttemure, montage | F24: A. Substructure - Bygningsbasis
B25: =B24+1 -> 22 | C25: A202004 | D25: A202004. Kælderydervægge, element, montage | E25: Kælderydervægge, element, montage | F25: A. Substructure - Bygningsbasis
... B54: =B53+1 -> 51 | C54: B2010 | D54: B2010. Exterior Walls - Udvendige Vægge | E54: Exterior Walls - Udvendige Vægge | F54: B. Shell - Lukning
A55: B10 | B55: =B54+1 -> 52 | C55: B201001 | D55: B201001. Søjler, leverance | E55: Søjler, leverance | F55: B. Shell - Råhus
A56: B10 | B56: =B55+1 -> 53 | C56: B201002 | D56: B201002. Søjler, montage | E56: Søjler, montage | F56: B. Shell - Råhus
B57: =B56+1 -> 54 | C57: B201003 | D57: B201003. Facader | E57: Facader | F57: B. Shell - Lukning
B58: =B57+1 -> 55 | C58: B201004 | D58: B201004. Øvrige - Facader | E58: Øvrige - Facader | F58: B. Shell - Råhus
A59: B10 | B59: =B58+1 -> 56 | C59: B201005 | D59: B201005. Beton elementvægge, leverance | E59: Beton elementvægge, leverance | F59: B. Shell - Råhus
A60: B10 | B60: =B59+1 -> 57 | C60: B201006 | D60: B201006. Beton elementvægge, montage | E60: Beton elementvægge, montage | F60: B. Shell - Råhus
A61: B10 | B61: =B60+1 -> 58 | C61: B201007 | D61: B201007. Stålsøjler | E61: Stålsøjler | F61: B. Shell - Råhus
B62: =B61+1 -> 59 | C62: B201008 | D62: B201008. Murværk, Letklinkeblokke, osv | E62: Murværk, Letklinkeblokke, osv | F62: B. Shell - Lukning
B63: =B62+1 -> 60 | C63: B201009 | D63: B201009. Porebetonskillevægge | E63: Porebetonskillevægge | F63: B. Shell - Lukning
B64: =B63+1 -> 61 | C64: B201010 | D64: B201010. Pudsarbejder | E64: Pudsarbejder | F64: B. Shell - Lukning
B65: =B64+1 -> 62 | C65: B201011 | D65: B201011. Solafskærmning | E65: Solafskærmning | F65: B. Shell - Lukning
A66: B10 | B66: =B65+1 -> 63 | C66: B201012 | D66: B201012. Brandisolering af stål | E66: Brandisolering af stål | F66: B. Shell - Råhus
B67: =B66+1 -> 64 | C67: B2020 | D67: B2020. Exterior Windows - Udvendige Vindue | E67: Exterior Windows - Udvendige Vindue | F67: B. Shell - Lukning
B68: =B67+1 -> 65 | C68: B202001 | D68: B202001. Etablering af vindue i fag | E68: Etablering af vindue i fag | F68: B. Shell - Lukning
B69: =B68+1 -> 66 | C69: B202002 | D69: B202002. Vinduesparti | E69: Vinduesparti | F69: B. Shell - Lukning
...

Sheet Template
A1: Position | B1: Sagsnr | C1: Position (Tilbudlist) | D1: Ydelse | E1: Mængde | F1: Enhed | G1: Mængde (bruttoareal) | H1: Enhedspris Tilbud 1 | I1: Pris i alt Tilbud 1 | J1: Enhedspris Tilbud 2 | K1: Pris i alt Tilbud 2 | L1: Enhedspris Tilbud 3 | M1: Pris i alt Tilbud 3 | N1: Enhedspris Tilbud 4 | O1: Pris i alt Tilbud 4 | P1: Enhedspris Tilbud 5 | Q1: Pris i alt Tilbud 5 | R1: Vinder Tilbud # | S1: Vinder tilbud enhedspris | T1: Vinder tilbud i alt | U1: Vinder tilbud kostpris /m2 | V1: Enhedspris (gns) | W1: I alt (gns) | X1: Kostpris (gns) / m2 | Y1: Højest tilbud # | Z1: Højest tilbud enhedspris | AA1: Højest tilbud i alt | AB1: Højest tilbud kostpris /m2 | AC1: Indeks | AD1: Indeks nr. | AE1: Dato | AF1: Niveau 1 | AG1: Niveau 2 | AH1: Niveau 3 | AI1: Benchmarking klassifikation | AJ1: Hvor mange gange | AK1: Tilbud 1 | AL1: Tilbud 2 | AM1: Tilbud 3 | AN1: Tilbud 4 | AO1: Tilbud 5 | AP1: Option | AQ1: Kommentarer (MOE)
A2: Do not delete this line | D2: Fill only columns marked orange in this row, yellow lines- copy the formula from above cells
A3: 01.01.01 | C3: Kopi fra TBL | D3: eksempler 1 | E3: 200 | F3: lbm | G3: 550 | H3: 450 | I3: =H3*$E3 -> 90000 | J3: 600 | K3: =J3*$E3 -> 120000 | L3: 700 | M3: =L3*$E3 -> 140000 | N3: 400 | O3: =N3*$E3 -> 80000 | P3: 400 | Q3: =P3*$E3 -> 80000 | R3: 1 | S3: =IF(R3=1,H3,IF(R3=2,J3,IF(R3=3,L3,IF(R3=4,N3,IF(R3=5,P3,"fejl"))))) -> 450 | T3: =IFERROR(S3*E3,0) -> 90000 | U3: =IFERROR(T3/G3,0) -> 163.63636 | V3: =IFERROR(SUM(H3,J3,L3,N3,P3)/SUM(IF(H3<>0,1,0),IF(J3<>0,1,0),IF(L3<>0,1,0),IF(N3<>0,1,0),IF(P3<>0,1,0)),0) -> 510 | W3: =IFERROR(V3*E3,0) -> 102000 | X3: =IFERROR(W3/G3,0) -> 185.45455 | Y3: 5 | Z3: =IF(Y3=1,H3,IF(Y3=2,J3,IF(Y3=3,L3,IF(Y3=4,N3,IF(Y3=5,P3,"fejl"))))) -> 400 | AA3: =IFERROR(Z3*E3,0) -> 80000 | AB3: =IFERROR(AA3/G3,0) -> 145.45455 | AC3: 2024K4 | AD3: 116.3 | AE3: 45658 | AF3: {=_xlfn.XLOOKUP($AH3,_xlfn.ANCHORARRAY(Xlookup_back!$F$3),Xlookup_back!$D$3:$D$87)} -> D. Services - Installationer | AG3: {=_xlfn.XLOOKUP($AH3,_xlfn.ANCHORARRAY(Xlookup_back!$F$3),Xlookup_back!$E$3:$E$87)} -> D10. Conveying Systems - Transportanlæg Systemer | AH3: D1020. Escalators & Moving Walks - Rulletrappe og rullende fortov | AI3: =IFERROR(VLOOKUP(AH3,Central_classifikation!$D$4:$F$408,3,FALSE),IFERROR(VLOOKUP(AG3,Central_classifikation!D:F,3,FALSE),IFERROR(VLOOKUP(AF3,Central_classifikation!D:F,3,FALSE),"-"))) -> D. El installationer | AJ3: =COUNTIF(D:D,D3) -> 1 | AK3: entreprenør 1 | AL3: entreprenør 2 | AM3: entreprenør 3 | AN3: entreprenør 4 | AO3: entreprenør 5 | AP3: no
A4: 01.01.02 | C4: Kopi fra TBL | D4: eksempler 4 | E4: 500 | F4: lbm | G4: 550 | H4: 15 | I4: =H4*$E4 -> 7500 | J4: 12 | K4: =J4*$E4 -> 6000 | L4: 60 | M4: =L4*$E4 -> 30000 | N4: 45 | O4: =N4*$E4 -> 22500 | P4: 15 | Q4: =P4*$E4 -> 7500 | R4: 1 | S4: =IF(R4=1,H4,IF(R4=2,J4,IF(R4=3,L4,IF(R4=4,N4,IF(R4=5,P4,"fejl"))))) -> 15 | T4: =IFERROR(S4*E4,0) -> 7500 | U4: =IFERROR(T4/G4,0) -> 13.636364 | V4: =IFERROR(SUM(H4,J4,L4,N4,P4)/SUM(IF(H4<>0,1,0),IF(J4<>0,1,0),IF(L4<>0,1,0),IF(N4<>0,1,0),IF(P4<>0,1,0)),0) -> 29.4 | W4: =IFERROR(V4*E4,0) -> 14700 | X4: =IFERROR(W4/G4,0) -> 26.727273 | Y4: 3 | Z4: =IF(Y4=1,H4,IF(Y4=2,J4,IF(Y4=3,L4,IF(Y4=4,N4,IF(Y4=5,P4,"fejl"))))) -> 60 | AA4: =IFERROR(Z4*E4,0) -> 30000 | AB4: =IFERROR(AA4/G4,0) -> 54.545455 | AC4: 2024K4 | AD4: 116.3 | AE4: 45658 | AF4: {=_xlfn.XLOOKUP($AH4,_xlfn.ANCHORARRAY(Xlookup_back!$F$3),Xlookup_back!$D$3:$D$87)} -> G. Building Sitework - Grund & Terræn arbejder | AG4: {=_xlfn.XLOOKUP($AH4,_xlfn.ANCHORARRAY(Xlookup_back!$F$3),Xlookup_back!$E$3:$E$87)} -> G30. Site Civil / Mechanical Utilities - Grund Bygge / VVS installationer | AH4: G3070. Other Civil / Mechanical Utilities – Øvrige Bygge / VVS installationer | AI4: =IFERROR(VLOOKUP(AH4,Central_classifikation!$D$4:$F$408,3,FALSE),IFERROR(VLOOKUP(AG4,Central_classifikation!D:F,3,FALSE),IFERROR(VLOOKUP(AF4,Central_classifikation!D:F,3,FALSE),"-"))) -> G. Building Sitework - Grund & Terræn arbejder | AJ4: =COUNTIF(D:D,D4) -> 1 | AK4: entreprenør 1 | AL4: entreprenør 2 | AM4: entreprenør 3 | AN4: entreprenør 4 | AO4: entreprenør 5 | AP4: no
A5: 01.02.01 | C5: Kopi fra TBL | D5: eksempler 2 | E5: 20 | F5: m³ | G5: 550 | H5: 5000 | I5: =H5*$E5 -> 100000 | J5: 4500 | K5: =J5*$E5 -> 90000 | L5: 5000 | M5: =L5*$E5 -> 100000 | N5: 0 | O5: 0 | P5: 0 | Q5: 0 | R5: 1 | S5: =IF(R5=1,H5,IF(R5=2,J5,IF(R5=3,L5,IF(R5=4,N5,IF(R5=5,P5,"fejl"))))) -> 5000 | T5: =IFERROR(S5*E5,0) -> 100000 | U5: =IFERROR(T5/G5,0) -> 181.81818 | V5: =IFERROR(SUM(H5,J5,L5,N5,P5)/SUM(IF(H5<>0,1,0),IF(J5<>0,1,0),IF(L5<>0,1,0),IF(N5<>0,1,0),IF(P5<>0,1,0)),0) -> 4833.3333 | W5: =IFERROR(V5*E5,0) -> 96666.667 | X5: =IFERROR(W5/G5,0) -> 175.75758 | Y5: 3 | Z5: =IF(Y5=1,H5,IF(Y5=2,J5,IF(Y5=3,L5,IF(Y5=4,N5,IF(Y5=5,P5,"fejl"))))) -> 5000 | AA5: =IFERROR(Z5*E5,0) -> 100000 | AB5: =IFERROR(AA5/G5,0) -> 181.81818 | AC5: 2024K4 | AD5: 116.3 | AE5: 45658 | AF5: {=_xlfn.XLOOKUP($AH5,_xlfn.ANCHORARRAY(Xlookup_back!$F$3),Xlookup_back!$D$3:$D$87)} -> A. Substructure - Bygningsbasis | AG5: {=_xlfn.XLOOKUP($AH5,_xlfn.ANCHORARRAY(Xlookup_back!$F$3),Xlookup_back!$E$3:$E$87)} -> A10. Foundations - Fundamenter | AH5: A1030. Slab on grade - Terrændæk | AI5: =IFERROR(VLOOKUP(AH5,Central_classifikation!$D$4:$F$408,3,FALSE),IFERROR(VLOOKUP(AG5,Central_classifikation!D:F,3,FALSE),IFERROR(VLOOKUP(AF5,Central_classifikation!D:F,3,FALSE),"-"))) -> A. Substructure - Bygningsbasis | AJ5: =COUNTIF(D:D,D5) -> 1 | AK5: entreprenør 1 | AL5: entreprenør 2 | AM5: entreprenør 3 | AN5: entreprenør 4 | AO5: entreprenør 5 | AP5: no
A6: 01.02.02 | R6: 1 | S6: =IF(R6=1,H6,IF(R6=2,J6,IF(R6=3,L6,IF(R6=4,N6,IF(R6=5,P6,"fejl"))))) -> 0 | T6: =IFERROR(S6*E6,0) -> 0 | U6: =IFERROR(T6/G6,0) -> 0 | V6: =IFERROR(SUM(H6,J6,L6,N6,P6)/SUM(IF(H6<>0,1,0),IF(J6<>0,1,0),IF(L6<>0,1,0),IF(N6<>0,1,0),IF(P6<>0,1,0)),0) -> 0 | W6: =IFERROR(V6*E6,0) -> 0 | X6: =IFERROR(W6/G6,0) -> 0 | Y6: 3 | Z6: =IF(Y6=1,H6,IF(Y6=2,J6,IF(Y6=3,L6,IF(Y6=4,N6,IF(Y6=5,P6,"fejl"))))) -> 0 | AA6: =IFERROR(Z6*E6,0) -> 0 | AB6: =IFERROR(AA6/G6,0) -> 0 | AC6: 2024K4 | AD6: 116.3 | AE6: 45658 | AF6: {=_xlfn.XLOOKUP($AH6,_xlfn.ANCHORARRAY(Xlookup_back!$F$3),Xlookup_back!$D$3:$D$87)} -> A. Substructure - Bygningsbasis | AG6: {=_xlfn.XLOOKUP($AH6,_xlfn.ANCHORARRAY(Xlookup_back!$F$3),Xlookup_back!$E$3:$E$87)} -> A10. Foundations - Fundamenter | AH6: A1030. Slab on grade - Terrændæk | AI6: =IFERROR(VLOOKUP(AH6,Central_classifikation!$D$4:$F$408,3,FALSE),IFERROR(VLOOKUP(AG6,Central_classifikation!D:F,3,FALSE),IFERROR(VLOOKUP(AF6,Central_classifikation!D:F,3,FALSE),"-"))) -> A. Substructure - Bygningsbasis | AJ6: =COUNTIF(D:D,D6) -> 0 | AK6: entreprenør 1 | AL6: entreprenør 2 | AM6: entreprenør 3 | AN6: entreprenør 4 | AO6: entreprenør 5 | AP6: yes
C8: Fill only columns marked orange in this row, for the rest- copy formulas
C9: Remember to copy this sheet, do not work in this sheet! | H9: In the columns H-Q with no data, leave it blank or write 0 | R9: Vinder tilbud is considered the winner tilbud for an entire package, not for seperate unit prices. | AF9: If you start classifying building elements from level 3, level 1, level 2 and Benchmarking klassifkation will fill up automatically
R10: Højest tilbud is considered the highest tilbud for an entire package, not for seperate unit prices.
C11: Checklist before the project is added to the databse. | O11: ="" | R11: If there is only 1 tilbud, put the same # in both winner and highest tilbud | AJ11: This column works as a check tool, to see if there are any repetative items
A12: No | C12: Do not work on the template, create new copy.
A13: No | C13: "Position" is filled and does follow accordingly the last project number in "projekter" sheet.
A14: No | C14: Fill "enhedspriser" and "pris i alt" for all tilbuds (columns H-Q). Make sure to copy in formulas in columns R-AA from the template.
A15: No | C15: Fill "vinder" (AB) and "højest" (AI) tilbud number. If there is only one offer, write for the "vinder #" and "højest #" the same number- 1.
A16: No | C16: Make sure index (AP-AQ) is as it is on an original offer.
A17: No | C17: For classification, select from the list on niveau 3 (AW), the rest of classification will fill in automatically. If in doubt what classification to use, ask others. It is important to have unifomr classification.
A18: No | C18: If there are optional prices in the offer, mark those lines in column "Option" (BE) as a "yes".
A19: No | C19: In "projekter" sheet, fill in ALL information about the project, as in the lines above.
A20: No | C20: Mark an all rows (1-xx) and columns (A-BE), click insert and create a table. Name this table "Tabel1"
A21: No | C21: Name the sheet with a project name.
A22: No | C22: Move the file to "Klar til at sættes ind"

Sheet Central template
B1: KLASSIFIKATIONSYSTEM: Uniformat Strukturen
B2: Niveau 1 | C2: Niveau 2 | D2: Niveau 3
B3: A. Substructure - Bygningsbasis | C3: A10. Foundations - Fundamenter | D3: A1010. Standard Foundations - Standard Fundamenter
B4: A. Substructure - Bygningsbasis | C4: A10. Foundations - Fundamenter | D4: A1020. Special Foundations - Specielle Fundamenter
B5: A. Substructure - Bygningsbasis | C5: A10. Foundations - Fundamenter | D5: A1030. Slab on grade - Terrændæk
B6: A. Substructure - Bygningsbasis | C6: A20. Basement Construction - Kælder konstruktion | D6: A2010. Basement Excavation - Jordarbejde
B7: A. Substructure - Bygningsbasis | C7: A20. Basement Construction - Kælder konstruktion | D7: A2020. Basement Walls - Inder - Yder- vægge kælder
B8: B. Shell - Råhus | C8: B10. Superstructure - Primære bygningsdele | D8: B1010. Floor Construction - Etage dæk konstruktion
B9: B. Shell - Råhus | C9: B10. Superstructure - Primære bygningsdele | D9: B1020. Roof Construction - Tag konstruktion
B10: B. Shell - Råhus | C10: B20. Exterior Closure - Udvendige arbejde | D10: B2010. Exterior Walls - Udvendige Vægge
B11: B. Shell - Råhus | C11: B20. Exterior Closure - Udvendige arbejde | D11: B2020. Exterior Windows - Udvendige Vindue
B12: B. Shell - Råhus | C12: B20. Exterior Closure - Udvendige arbejde | D12: B2030. Exterior Doors - Udvendige Døre
B13: B. Shell - Råhus | C13: B30. Roofing - Tag | D13: B3010. Roof Coverings - Tag dækning
... B87: G. Building Sitework - Grund & Terræn arbejder | C87: G50. Other Site Construction – Øvrige Terræn Konstruktion | D87: G5020. Other Site Systems & Equipment – Øvrige Terræn Systemer & Inventar

Sheet MOE2
A1: Position | B1: Position Tilbud | C1: Ydelse | D1: Mængde | E1: Enhed | F1: Mængde (bruttoareal) | G1: (N) Ny (O) Ombygning (Ne) Nedrives | H1: Enhedspris Tilbud 1 | I1: Pris i alt Tilbud 1 | J1: Enhedspris Tilbud 2 | K1: Pris i alt Tilbud 2 | L1: Enhedspris Tilbud 3 | M1: Pris i alt Tilbud 3 | N1: Enhedspris Tilbud 4 | O1: Pris i alt Tilbud 4 | P1: Enhedspris (gns) | Q1: Kostpris (gns) | R1: Kostpris / m2 | S1: Indeks | T1: Indeks nr. | U1: Projekt navn | V1: Projekt type | W1: Niveau 1 | X1: Niveau 2 | Y1: Niveau 3 | Z1: Niveau 4 | AA1: Niveau 5 | AB1: Hvor mange gange | AC1: Kommentarer (MOE) | AD1: Tilbud 1 | AE1: Tilbud 2 | AF1: Tilbud 3 | AG1: Tilbud 4
A3: 21.01 | C3: Terrænarbejder
A4: 21.01.01 | C4: Generelt
A5: 21.01.02 | C5: Midlertidig omlægning af busterminal samt retablering
A6: 21.02 | C6: Bygningsbasis
A7: 21.02.01 | C7: Fundamenter
A8: 21.02.02 | C8: Fundamenter revurderet
A9: 21.03 | C9: Primære bygningsdele
A10: 21.03.01 | C10: P-dæk
A11: 21.03.02 | C11: Kontor
A12: 21.03.03 | C12: Tillæg for gitterkonstruktion
A13: 21.03.04 | C13: Tillæg for sammenbygning
A14: 21.04 | C14: Komplettering
... A27: 21.07.03 | C27: Håndværkerudgifter
C28: INDEXERING 2015K1 - 2016K2:
C29: Totalentreprenør dækningsbidrag
C30: Totalentreprenør risikopulje
C31: Totalentreprenør udførelses risiko
C32: Uforudsete
C33: Byggeplads
C34: Entreprisesum, TE Heraf indregnet 10% til UE-salær
